<?xml version="1.0"?>
<sdf version="1.9">
    <model name="parrot_nova_2">
        <link name="body">
        <pose>0 0 0 0 0 0</pose>
        <inertial>
            <mass>0.503</mass> <!-- kg -->
            <inertia> <!-- kg.m^2 -->
                <ixx>1.805e-3</ixx>
                <ixy>-8.619e-7</ixy>
                <iyy>1.764e-3</iyy>
                <ixz>1.555e-5</ixz>
                <iyz>3.595e-7</iyz>
                <izz>3.328e-3</izz>
            </inertia>
        </inertial>

        <collision name="body_inertia_collision">
            <pose>-0.00424 0.00014 -0.00595 0 0 0</pose>
            <geometry>
                <box>
                    <size>0.316618 0.330564 0.089582</size>
                </box>
            </geometry>
            <max_contacts>10</max_contacts>
            <surface>
                <bounce>
                    <restitution_coefficient>0.828</restitution_coefficient>
                    <threshold>0</threshold>
                </bounce>
                <friction>
                    <ode>
                        <mu>10</mu>
                        <mu2>5</mu2>
                        <fdir1>0 0 0</fdir1>
                        <slip1>0.0</slip1>
                        <slip2>0.0</slip2>
                    </ode>
                </friction>
                <contact>
                    <ode>
                        <kp>10000.0</kp>
                        <kd>10.0</kd>
                        <max_vel>0.01</max_vel>
                        <min_depth>0</min_depth>
                    </ode>
                </contact>
            </surface>
        </collision>


        <visual name="body_inertia_visual">
            <geometry>
                <mesh>
                    <uri>model://parrot_nova_2/meshes/hull.dae</uri>
                </mesh>
            </geometry>
        </visual>

        <sensor name="nova_imu" type="imu">
            <always_on>0</always_on>
            <update_rate>100</update_rate>
            <visualize>true</visualize>
            <topic>nova/imu</topic>
            <enable_metrics>true</enable_metrics>
        </sensor>

        <sensor name="nova_altimeter" type="altimeter">
          <always_on>0</always_on>
          <update_rate>30</update_rate>
          <visualize>true</visualize>
          <topic>nova/altimeter</topic>
          <enable_metrics>true</enable_metrics>
          <altimeter>
            <vertical_position>
              <noise type="gaussian">
                <mean>0.1</mean>
                <stddev>0.2</stddev>
              </noise>
            </vertical_position>
            <vertical_velocity>
              <noise type="gaussian">
                <mean>0.2</mean>
                <stddev>0.1</stddev>
              </noise>
            </vertical_velocity>
          </altimeter>
        </sensor>

        </link>

        <link name='propeller_rr'>
        <pose>-0.09035 -0.11423 -0.00501 0 0 0</pose>
        <inertial>
            <mass>0.005</mass>
            <inertia>
                <ixx>9.75e-07</ixx>
                <iyy>4.17041e-05</iyy>
                <izz>4.26041e-05</izz>
            </inertia>
        </inertial>

        <visual name="propeller_rr_visual">
            <geometry>
                <mesh>
                    <uri>model://parrot_nova_2/meshes/propeller_rr.dae</uri>
                </mesh>
            </geometry>
        </visual>
        </link>

        <joint name='propeller_rr_joint' type='revolute'>
            <child>propeller_rr</child>
            <parent>body</parent>
            <axis>
                <xyz>0 0 1</xyz>
            </axis>
        </joint>

        <link name='propeller_rl'>
        <pose>-0.09035 0.11452 -0.00501 0 0 0</pose>
        <inertial>
            <mass>0.005</mass>
            <inertia>
                <ixx>9.75e-07</ixx>
                <iyy>4.17041e-05</iyy>
                <izz>4.26041e-05</izz>
            </inertia>
        </inertial>

        <visual name="propeller_rl_visual">
            <geometry>
                <mesh>
                    <uri>model://parrot_nova_2/meshes/propeller_rl.dae</uri>
                </mesh>
            </geometry>
        </visual>
        </link>

        <joint name='propeller_rl_joint' type='revolute'>
            <child>propeller_rl</child>
            <parent>body</parent>
            <axis>
                <xyz>0 0 1</xyz>
            </axis>
        </joint>

        <link name='propeller_fr'>
        <pose>0.08456 -0.11435 -0.00501 0 0 0</pose>
        <inertial>
            <mass>0.005</mass>
            <inertia>
                <ixx>9.75e-07</ixx>
                <iyy>4.17041e-05</iyy>
                <izz>4.26041e-05</izz>
            </inertia>
        </inertial>

        <visual name="propeller_fr_visual">
            <geometry>
                <mesh>
                    <uri>model://parrot_nova_2/meshes/propeller_fr.dae</uri>
                </mesh>
            </geometry>
        </visual>
        </link>

        <joint name='propeller_fr_joint' type='revolute'>
            <child>propeller_fr</child>
            <parent>body</parent>
            <axis>
                <xyz>0 0 1</xyz>
            </axis>
        </joint>

        <!-- Propeller FL -->
        <link name='propeller_fl'>
        <pose>0.08456 0.11463 -0.00501 0 0 0</pose>
        <inertial>
            <mass>0.005</mass>
            <inertia>
                <ixx>9.75e-07</ixx>
                <iyy>4.17041e-05</iyy>
                <izz>4.26041e-05</izz>
            </inertia>
        </inertial>

        <visual name="propeller_fl_visual">
            <geometry>
                <mesh>
                    <uri>model://parrot_nova_2/meshes/propeller_fl.dae</uri>
                </mesh>
            </geometry>
        </visual>
        </link>

        <joint name='propeller_fl_joint' type='revolute'>
            <child>propeller_fl</child>
            <parent>body</parent>
            <axis>
                <xyz>0 0 1</xyz>
            </axis>
        </joint>

        <plugin
            filename="gz-sim-pose-publisher-system"
            name="gz::sim::systems::PosePublisher">
            <publish_link_pose>true</publish_link_pose>
            <publish_sensor_pose>false</publish_sensor_pose>
            <publish_collision_pose>false</publish_collision_pose>
            <publish_visual_pose>true</publish_visual_pose>
            <publish_nested_model_pose>false</publish_nested_model_pose>
        </plugin>
    </model>
</sdf>